<?xml version='1.0'?>

<robot name="my_robot" xmlns:xacro="http://www.ros.org/wiki/xacro">
<!--<xacro:property name="wheel_origin">
  <geometry type="cylinder" radius="0.1" length="0.05" />
  <origin xyz="0 0 0" rpy="0 1.5707 1.5707" />
</xacro:property>-->
<xacro:macro name="wheel" params="side">
  <link name="${side}_wheel">
    <collision name='collision'>
        <geometry type="cylinder" radius="0.1" length="0.05" />
  <origin xyz="0 0 0" rpy="0 1.5707 1.5707" />
    </collision>
    <visual name='chassis_visual'>
      <!--<xacro:insert_block name="wheel_origin" />-->
        <geometry type="cylinder" radius="0.1" length="0.05" />
  <origin xyz="0 0 0" rpy="0 1.5707 1.5707" />
    </visual>  
    <inertial>
      <mass value="5.0"/>
      <origin xyz="0.0 0 0" rpy=" 0 0 0"/>
      <inertia
          ixx="0.1" ixy="0" ixz="0"
          iyy="0.1" iyz="0"
          izz="0.1"
      />
    </inertial>
  </link>
  <joint type="continuous" name="${side}_wheel_hinge">
    <origin xyz="0 0.15 0" rpy="0 0 0"/>
    <child link="${side}_wheel"/>
    <parent link="chassis"/>
    <axis xyz="0 1 0" rpy="0 0 0"/>
    <limit effort="10000" velocity="1000"/>
    <dynamics damping="1.0" friction="1.0"/>
  </joint>



</xacro:macro>
</robot>